Workbook

Sheet Report
A1: CandiVue AI: Gemini Token Consumption (estimate)
A2: [Your name] (ID 30225) · Source: estimate from prompt sizes in the code and the days AI features were built and tested · 2026-10-06 to 2026-10-27 · Gemini free tier
A4: Model | B4: AI calls | C4: Input tokens | D4: Output tokens | E4: Thinking tokens | F4: Total tokens | G4: Avg tokens per call
A5: gemini-3.5-flash-lite | B5: =ROUND(SUMPRODUCT('Calls per day'!$L$4:$L$12,'Estimate inputs'!D$5:D$13),0) | C5: =ROUND(SUMPRODUCT('Calls per day'!$L$4:$L$12,'Estimate inputs'!D$5:D$13,'Estimate inputs'!$B$5:$B$13),0) | D5: =ROUND(SUMPRODUCT('Calls per day'!$L$4:$L$12,'Estimate inputs'!D$5:D$13,'Estimate inputs'!$C$5:$C$13),0) | E5: - | F5: =C5+D5 | G5: =IF(B5=0,0,F5/B5)
A6: gemini-3.5-flash | B6: =ROUND(SUMPRODUCT('Calls per day'!$L$4:$L$12,'Estimate inputs'!E$5:E$13),0) | C6: =ROUND(SUMPRODUCT('Calls per day'!$L$4:$L$12,'Estimate inputs'!E$5:E$13,'Estimate inputs'!$B$5:$B$13),0) | D6: =ROUND(SUMPRODUCT('Calls per day'!$L$4:$L$12,'Estimate inputs'!E$5:E$13,'Estimate inputs'!$C$5:$C$13),0) | E6: - | F6: =C6+D6 | G6: =IF(B6=0,0,F6/B6)
A7: gemini-3.1-flash-lite | B7: =ROUND(SUMPRODUCT('Calls per day'!$L$4:$L$12,'Estimate inputs'!F$5:F$13),0) | C7: =ROUND(SUMPRODUCT('Calls per day'!$L$4:$L$12,'Estimate inputs'!F$5:F$13,'Estimate inputs'!$B$5:$B$13),0) | D7: =ROUND(SUMPRODUCT('Calls per day'!$L$4:$L$12,'Estimate inputs'!F$5:F$13,'Estimate inputs'!$C$5:$C$13),0) | E7: - | F7: =C7+D7 | G7: =IF(B7=0,0,F7/B7)
A8: Total | B8: =SUM(B5:B7) | C8: =SUM(C5:C7) | D8: =SUM(D5:D7) | E8: - | F8: =C8+D8 | G8: =IF(B8=0,0,F8/B8)
A10: These are estimates: CandiVue does not log token counts. Exact numbers are on Google's usage page (ai.dev/rate-limit).
A11: Not included: thinking tokens, embeddings (local model), the local screening model and automated tests (fake LLM). See the input sheets.
A13: Token consumption by workflow
A14: Workflow | B14: AI calls | C14: Input tokens | D14: Output tokens | E14: Thinking tokens | F14: Total tokens | G14: Avg tokens per call
A15: Hiring Assistant chat | B15: ='Calls per day'!L4 | C15: =B15*'Estimate inputs'!B5 | D15: =B15*'Estimate inputs'!C5 | E15: - | F15: =C15+D15 | G15: =IF(B15=0,0,F15/B15)
A16: JD writing | B16: ='Calls per day'!L5 | C16: =B16*'Estimate inputs'!B6 | D16: =B16*'Estimate inputs'!C6 | E16: - | F16: =C16+D16 | G16: =IF(B16=0,0,F16/B16)
A17: CV screening | B17: ='Calls per day'!L6 | C17: =B17*'Estimate inputs'!B7 | D17: =B17*'Estimate inputs'!C7 | E17: - | F17: =C17+D17 | G17: =IF(B17=0,0,F17/B17)
A18: Talent rediscovery | B18: ='Calls per day'!L7 | C18: =B18*'Estimate inputs'!B8 | D18: =B18*'Estimate inputs'!C8 | E18: - | F18: =C18+D18 | G18: =IF(B18=0,0,F18/B18)
A19: Q&A analysis | B19: ='Calls per day'!L8 | C19: =B19*'Estimate inputs'!B9 | D19: =B19*'Estimate inputs'!C9 | E19: - | F19: =C19+D19 | G19: =IF(B19=0,0,F19/B19)
A20: Interview review (F8-F10) | B20: ='Calls per day'!L9 | C20: =B20*'Estimate inputs'!B10 | D20: =B20*'Estimate inputs'!C10 | E20: - | F20: =C20+D20 | G20: =IF(B20=0,0,F20/B20)
A21: Assessment report | B21: ='Calls per day'!L10 | C21: =B21*'Estimate inputs'!B11 | D21: =B21*'Estimate inputs'!C11 | E21: - | F21: =C21+D21 | G21: =IF(B21=0,0,F21/B21)
A22: AI Helper (live room) | B22: ='Calls per day'!L11 | C22: =B22*'Estimate inputs'!B12 | D22: =B22*'Estimate inputs'!C12 | E22: - | F22: =C22+D22 | G22: =IF(B22=0,0,F22/B22)
A23: CV interview questions | B23: ='Calls per day'!L12 | C23: =B23*'Estimate inputs'!B13 | D23: =B23*'Estimate inputs'!C13 | E23: - | F23: =C23+D23 | G23: =IF(B23=0,0,F23/B23)
A24: Total | B24: =SUM(B15:B23) | C24: =SUM(C15:C23) | D24: =SUM(D15:D23) | E24: - | F24: =C24+D24 | G24: =IF(B24=0,0,F24/B24)
A26: Workflow = the part of CandiVue that sends the request to Gemini (see app/ai/llm.py, invoke_llm).
A29: Token consumption by day
A30: Date | B30: AI calls | C30: Input tokens | D30: Output tokens | E30: Thinking tokens | F30: Total tokens | G30: Avg tokens per call
A31: 2026-10-06 | B31: =SUM('Calls per day'!B$4:B$12) | C31: =SUMPRODUCT('Calls per day'!B$4:B$12,'Estimate inputs'!$B$5:$B$13) | D31: =SUMPRODUCT('Calls per day'!B$4:B$12,'Estimate inputs'!$C$5:$C$13) | E31: - | F31: =C31+D31 | G31: =IF(B31=0,0,F31/B31)
A32: 2026-10-07 | B32: =SUM('Calls per day'!C$4:C$12) | C32: =SUMPRODUCT('Calls per day'!C$4:C$12,'Estimate inputs'!$B$5:$B$13) | D32: =SUMPRODUCT('Calls per day'!C$4:C$12,'Estimate inputs'!$C$5:$C$13) | E32: - | F32: =C32+D32 | G32: =IF(B32=0,0,F32/B32)
A33: 2026-10-08 | B33: =SUM('Calls per day'!D$4:D$12) | C33: =SUMPRODUCT('Calls per day'!D$4:D$12,'Estimate inputs'!$B$5:$B$13) | D33: =SUMPRODUCT('Calls per day'!D$4:D$12,'Estimate inputs'!$C$5:$C$13) | E33: - | F33: =C33+D33 | G33: =IF(B33=0,0,F33/B33)
A34: 2026-10-11 | B34: =SUM('Calls per day'!E$4:E$12) | C34: =SUMPRODUCT('Calls per day'!E$4:E$12,'Estimate inputs'!$B$5:$B$13) | D34: =SUMPRODUCT('Calls per day'!E$4:E$12,'Estimate inputs'!$C$5:$C$13) | E34: - | F34: =C34+D34 | G34: =IF(B34=0,0,F34/B34)
A35: 2026-10-13 | B35: =SUM('Calls per day'!F$4:F$12) | C35: =SUMPRODUCT('Calls per day'!F$4:F$12,'Estimate inputs'!$B$5:$B$13) | D35: =SUMPRODUCT('Calls per day'!F$4:F$12,'Estimate inputs'!$C$5:$C$13) | E35: - | F35: =C35+D35 | G35: =IF(B35=0,0,F35/B35)
A36: 2026-10-15 | B36: =SUM('Calls per day'!G$4:G$12) | C36: =SUMPRODUCT('Calls per day'!G$4:G$12,'Estimate inputs'!$B$5:$B$13) | D36: =SUMPRODUCT('Calls per day'!G$4:G$12,'Estimate inputs'!$C$5:$C$13) | E36: - | F36: =C36+D36 | G36: =IF(B36=0,0,F36/B36)
A37: 2026-10-17 | B37: =SUM('Calls per day'!H$4:H$12) | C37: =SUMPRODUCT('Calls per day'!H$4:H$12,'Estimate inputs'!$B$5:$B$13) | D37: =SUMPRODUCT('Calls per day'!H$4:H$12,'Estimate inputs'!$C$5:$C$13) | E37: - | F37: =C37+D37 | G37: =IF(B37=0,0,F37/B37)
A38: 2026-10-18 | B38: =SUM('Calls per day'!I$4:I$12) | C38: =SUMPRODUCT('Calls per day'!I$4:I$12,'Estimate inputs'!$B$5:$B$13) | D38: =SUMPRODUCT('Calls per day'!I$4:I$12,'Estimate inputs'!$C$5:$C$13) | E38: - | F38: =C38+D38 | G38: =IF(B38=0,0,F38/B38)
A39: 2026-10-22 | B39: =SUM('Calls per day'!J$4:J$12) | C39: =SUMPRODUCT('Calls per day'!J$4:J$12,'Estimate inputs'!$B$5:$B$13) | D39: =SUMPRODUCT('Calls per day'!J$4:J$12,'Estimate inputs'!$C$5:$C$13) | E39: - | F39: =C39+D39 | G39: =IF(B39=0,0,F39/B39)
A40: 2026-10-23 | B40: =SUM('Calls per day'!K$4:K$12) | C40: =SUMPRODUCT('Calls per day'!K$4:K$12,'Estimate inputs'!$B$5:$B$13) | D40: =SUMPRODUCT('Calls per day'!K$4:K$12,'Estimate inputs'!$C$5:$C$13) | E40: - | F40: =C40+D40 | G40: =IF(B40=0,0,F40/B40)
A41: Total | B41: =SUM(B31:B40) | C41: =SUM(C31:C40) | D41: =SUM(D31:D40) | E41: - | F41: =C41+D41 | G41: =IF(B41=0,0,F41/B41)
A44: Pre-project estimate (planned before building)
A45: What I would have estimated at the start (4 Oct 2026), from the requirements only: the core features, the 20-CV sample batch and the planned test runs. Edit the yellow cells.
A46: Workflow | B46: Planned test runs | C46: AI calls per run | D46: Planned AI calls | E46: Tokens per call (guess) | F46: Planned tokens | G46: Current estimate | H46: Difference
A47: Hiring Assistant chat | B47: 15 | C47: 8 | D47: =B47*C47 | E47: 1500 | F47: =D47*E47 | G47: =F15 | H47: =G47-F47
A48: JD writing | B48: 15 | C48: 2 | D48: =B48*C48 | E48: 2500 | F48: =D48*E48 | G48: =F16 | H48: =G48-F48
...

Sheet Estimate inputs
A1: Estimate inputs (edit the yellow cells; the Report sheet updates)
A2: Tokens = characters / 4. Character counts were measured from the prompts, schemas and tool definitions in the code on 27 Oct 2026.
A4: Workflow | B4: Input tokens per call | C4: Output tokens per call | D4: Share gemini-3.5-flash-lite | E4: Share gemini-3.5-flash | F4: Share gemini-3.1-flash-lite | G4: How the size was estimated
A5: Hiring Assistant chat | B5: 4850 | C5: 90 | D5: 0.8 | E5: 0.12 | F5: 0.08 | G5: System prompt 5,418 + tool definitions 10,453 + job context ~500 + chat history ~3,000 chars. Output: a short reply or a tool call.
A6: JD writing | B6: 1800 | C6: 650 | D6: 0.8 | E6: 0.12 | F6: 0.08 | G6: JD prompt 1,608 + schema 1,085 + profile JSON ~1,500 + reference passages ~3,000 chars. Output: a full JD (~2,600 chars).
A7: CV screening | B7: 1050 | C7: 110 | D7: 1 | E7: 0 | F7: 0 | G7: Years check (prompt 419 + schema 473) or requirement check (390 + 723) + CV text ~3,000 chars (max 6,000). Gemini only since 23 Oct; before that the local model did these checks (0 Gemini tokens).
A8: Talent rediscovery | B8: 1050 | C8: 110 | D8: 1 | E8: 0 | F8: 0 | G8: Uses the same AI checks as CV screening (Gemini since 23 Oct).
A9: Q&A analysis | B9: 2250 | C9: 450 | D9: 0.8 | E9: 0.12 | F9: 0.08 | G9: Two calls per run: segmentation (prompt 1,503 + schema 1,137 + transcript ~4,000 chars) and answer evaluation (1,545 + 1,745 + answers and RAG passages ~7,000 chars).
A10: Interview review (F8-F10) | B10: 3100 | C10: 500 | D10: 0.8 | E10: 0.12 | F10: 0.08 | G10: Review prompt 2,032 + schema 2,405 + CV items, scored answers and transcript ~8,000 chars.
A11: Assessment report | B11: 2550 | C11: 380 | D11: 0.8 | E11: 0.12 | F11: 0.08 | G11: Findings prompt 1,521 + schema 1,044 + report context ~8,000 chars; about 1 in 4 reports needs a repair call (prompt 753 + schema 670).
A12: AI Helper (live room) | B12: 1700 | C12: 100 | D12: 0.8 | E12: 0.12 | F12: 0.08 | G12: Room prompt 2,175 + room tools 2,609 + context and history ~2,000 chars.
A13: CV interview questions | B13: 800 | C13: 250 | D13: 0.8 | E13: 0.12 | F13: 0.08 | G13: Prompt 619 + schema 727 + requirements and CV summary ~1,800 chars. Output: 5 questions.

Sheet Calls per day
A1: Estimated AI calls per day (edit the yellow cells)
A3: Workflow | B3: 2026-10-06 | C3: 2026-10-07 | D3: 2026-10-08 | E3: 2026-10-11 | F3: 2026-10-13 | G3: 2026-10-15 | H3: 2026-10-17 | I3: 2026-10-18 | J3: 2026-10-22 | K3: 2026-10-23 | L3: Total
A4: Hiring Assistant chat | B4: 60 | C4: 10 | D4: 12 | E4: 40 | F4: 25 | G4: 8 | H4: 15 | I4: 6 | J4: 6 | K4: 14 | L4: =SUM(B4:K4)
A5: JD writing | B5: 18 | C5: 3 | D5: 3 | E5: 5 | F5: 2 | G5: 0 | H5: 2 | I5: 1 | J5: 1 | K5: 2 | L5: =SUM(B5:K5)
A6: CV screening | B6: 0 | C6: 0 | D6: 0 | E6: 0 | F6: 0 | G6: 0 | H6: 0 | I6: 0 | J6: 0 | K6: 24 | L6: =SUM(B6:K6)
A7: Talent rediscovery | B7: 0 | C7: 0 | D7: 0 | E7: 0 | F7: 0 | G7: 0 | H7: 0 | I7: 0 | J7: 0 | K7: 6 | L7: =SUM(B7:K7)
A8: Q&A analysis | B8: 0 | C8: 0 | D8: 0 | E8: 0 | F8: 0 | G8: 0 | H8: 16 | I8: 8 | J8: 8 | K8: 2 | L8: =SUM(B8:K8)
A9: Interview review (F8-F10) | B9: 0 | C9: 0 | D9: 0 | E9: 0 | F9: 0 | G9: 0 | H9: 8 | I9: 4 | J9: 4 | K9: 1 | L9: =SUM(B9:K9)
A10: Assessment report | B10: 0 | C10: 0 | D10: 0 | E10: 0 | F10: 0 | G10: 0 | H10: 10 | I10: 5 | J10: 6 | K10: 1 | L10: =SUM(B10:K10)
A11: AI Helper (live room) | B11: 0 | C11: 0 | D11: 0 | E11: 0 | F11: 30 | G11: 6 | H11: 6 | I11: 4 | J11: 3 | K11: 4 | L11: =SUM(B11:K11)
A12: CV interview questions | B12: 0 | C12: 0 | D12: 0 | E12: 0 | F12: 10 | G12: 3 | H12: 3 | I12: 2 | J12: 2 | K12: 1 | L12: =SUM(B12:K12)
A14: Days = the days AI code was committed (git log). Calls per day follow how much each AI feature was worked on and tested that day.
A15: Anchor: the app's own request counter shows 43 requests to gemini-3.5-flash-lite on 23 Oct 2026, the last day it recorded.
A16: Not included: thinking tokens, embedding calls (local Ollama model), the local screening model, and automated tests (they use a fake LLM).
